<?xml version="1.0" encoding="utf-8"?>
<!-- This URDF was automatically created by SolidWorks to URDF Exporter! Originally created by Stephen Brawner (brawner@gmail.com) 
     Commit Version: 1.6.0-4-g7f85cfe  Build Version: 1.6.7995.38578
     For more information, please see http://wiki.ros.org/sw_urdf_exporter -->
<robot
  name="biped_v2">
  <link name="torso">
    <inertial>
      <origin
        xyz="0.0089994 4.841E-05 0.0711"
        rpy="0 0 0" />
      <mass
        value="26.21" />
      <inertia
        ixx="0.04753"
        ixy="8.2124E-07"
        ixz="0.0012659"
        iyy="0.024162"
        iyz="4.7311E-07"
        izz="0.043368" />
    </inertial>
    <visual>
      <origin
        xyz="0 0 0"
        rpy="0 0 0" />
      <geometry>
        <mesh
          filename="../meshes/torso.obj" />
      </geometry>
      <material
        name="">
        <color
          rgba="0.75294 0.75294 0.75294 1" />
      </material>
    </visual>
  </link>
  <link name="l_uleg_z">
    <inertial>
      <origin
        xyz="-0.086894 1.1718E-10 -0.019971"
        rpy="0 0 0" />
      <mass
        value="0.23915" />
      <inertia
        ixx="0.00019621"
        ixy="2.8207E-08"
        ixz="-0.00020599"
        iyy="0.000693"
        iyz="2.8208E-08"
        izz="0.00052444" />
    </inertial>
    <visual>
      <origin
        xyz="0 0 0"
        rpy="0 0 0" />
      <geometry>
        <mesh
          filename="../meshes/l_uleg_z.obj" />
      </geometry>
      <material
        name="">
        <color
          rgba="0.86667 0.86667 0.8902 1" />
      </material>
    </visual>
  </link>
  <joint name="l_hip_z"
    type="revolute">
    <origin
      xyz="0 0.11 -0.0965"
      rpy="0 0 0" />
    <parent
      link="torso" />
    <child
      link="l_uleg_z" />
    <axis
      xyz="0 0 1" />
    <limit
      lower="-1.57"
      upper="1.57"
      effort="48"
      velocity="25" />
  </joint>
  <transmission type="SimpleTransmission">
    <joint name="l_hip_z"/>
    <actuator name="l_hip_z_motor">
      <drake:gear_ratio value="9.0" />
      <drake:rotor_inertia value="0.0001002" />
    </actuator>
  </transmission>
  <link name="l_uleg_x">
    <inertial>
      <origin
        xyz="0.091572 -0.03382 -4.1689E-05"
        rpy="0 0 0" />
      <mass
        value="2.4984" />
      <inertia
        ixx="0.002874"
        ixy="0.00028125"
        ixz="7.8653E-07"
        iyy="0.0035088"
        iyz="1.2225E-07"
        izz="0.0028211" />
    </inertial>
    <visual>
      <origin
        xyz="0 0 0"
        rpy="0 0 0" />
      <geometry>
        <mesh
          filename="../meshes/l_uleg_x.obj" />
      </geometry>
      <material
        name="">
        <color
          rgba="0.75294 0.75294 0.75294 1" />
      </material>
    </visual>
  </link>
  <joint name="l_hip_x"
    type="revolute">
    <origin
      xyz="-0.1335 0 -0.08"
      rpy="0 0 0" />
    <parent
      link="l_uleg_z" />
    <child
      link="l_uleg_x" />
    <axis
      xyz="1 0 0" />
    <limit
      lower="-0.78"
      upper="1.57"
      effort="48"
      velocity="25" />
  </joint>
  <transmission type="SimpleTransmission">
    <joint name="l_hip_x"/>
    <actuator name="l_hip_x_motor">
      <drake:gear_ratio value="9.0" />
      <drake:rotor_inertia value="0.0001002" />
    </actuator>
  </transmission>
  <link name="l_uleg">
    <inertial>
      <origin
        xyz="0.00102 0.018509 -0.021513"
        rpy="0 0 0" />
      <mass
        value="2.2508" />
      <inertia
        ixx="0.007381"
        ixy="-3.1108E-05"
        ixz="0.00037536"
        iyy="0.0095158"
        iyz="0.00052692"
        izz="0.0025951" />
    </inertial>
    <visual>
      <origin
        xyz="0 0 0"
        rpy="0 0 0" />
      <geometry>
        <mesh
          filename="../meshes/l_uleg.obj" />
      </geometry>
      <material
        name="">
        <color
          rgba="0.75294 0.75294 0.75294 1" />
      </material>
    </visual>
  </link>
  <joint name="l_hip_y"
    type="revolute">
    <origin
      xyz="0.1355 -0.00 0"
      rpy="0 0 0" />
    <parent
      link="l_uleg_x" />
    <child
      link="l_uleg" />
    <axis
      xyz="0 1 0" />
    <limit
      lower="-2.35"
      upper="0.78"
      effort="74"
      velocity="47" />
  </joint>
  <transmission type="SimpleTransmission">
    <joint name="l_hip_y"/>
    <actuator name="l_hip_y_motor">
      <drake:gear_ratio value="9.0" />
      <drake:rotor_inertia value="0.0001002" />
    </actuator>
  </transmission>
  <link name="l_knee_dummy">
    <inertial>
      <origin xyz="0 0 0" rpy="0 0 0"/>
      <mass value="0.1"/>
      <inertia ixx="1e-4" iyy="1e-4" izz="1e-4"/>
    </inertial>
  </link>
  <joint name="l_knee_dummy" type="revolute">
    <origin xyz="0 0.03365 -0.23" rpy="0 0 0"/>
    <parent link="l_uleg"/>
    <child link="l_knee_dummy"/>
    <axis xyz="0 1 0"/>
    <limit upper="3.14" lower="-3.14"/>
    <dynamics damping="0"/>
  </joint>
  <drake:linear_bushing_rpy>
    <drake:bushing_frameA name="l_uleg"/>
    <drake:bushing_frameC name="l_knee_dummy"/>
    <drake:bushing_force_damping value="0 0 0"/>
    <drake:bushing_force_stiffness value="0 0 0"/>
    <drake:bushing_torque_damping value="0 10 0"/>
    <drake:bushing_torque_stiffness value="0 3000 0"/>
  </drake:linear_bushing_rpy>
  <link name="l_lleg">
    <inertial>
      <origin
        xyz="-4.8585E-05 -0.03165 -0.018299"
        rpy="0 0 0" />
      <mass
        value="1.3508" />
      <inertia
        ixx="0.0040885"
        ixy="-1.8264E-07"
        ixz="3.2084E-07"
        iyy="0.0046773"
        iyz="-5.8388E-05"
        izz="0.0010996" />
    </inertial>
    <visual>
      <origin
        xyz="0 0 0"
        rpy="0 0 0" />
      <geometry>
        <mesh
          filename="../meshes/l_lleg.obj" />
      </geometry>
      <material
        name="">
        <color
          rgba="0.75294 0.75294 0.75294 1" />
      </material>
    </visual>
  </link>
  <joint name="l_knee"
    type="revolute">
    <origin
      xyz="0 0 0"
      rpy="0 0 0" />
    <parent
      link="l_knee_dummy" />
    <child
      link="l_lleg" />
    <axis
      xyz="0 1 0" />
    <limit
      lower="-0.174"
      upper="2.61"
      effort="74"
      velocity="47" />
  </joint>
  <transmission type="SimpleTransmission">
    <joint name="l_knee"/>
    <actuator name="l_knee_motor">
      <drake:gear_ratio value="9.0" />
      <drake:rotor_inertia value="0.0001002" />
    </actuator>
  </transmission>
  <link name="l_foot">
    <inertial>
      <origin
        xyz="-0.0017103 -0.0012414 -0.028758"
        rpy="0 0 0" />
      <mass
        value="0.19291" />
      <inertia
        ixx="6.7544E-05"
        ixy="-5.0585E-06"
        ixz="1.3775E-05"
        iyy="0.00030983"
        iyz="9.9132E-06"
        izz="0.00027205" />
    </inertial>
    <visual>
      <origin
        xyz="0 0 0"
        rpy="0 0 0" />
      <geometry>
        <mesh
          filename="../meshes/l_foot.obj" />
      </geometry>
      <material
        name="">
        <color
          rgba="0.75294 0.75294 0.75294 1" />
      </material>
    </visual>
    <visual>
      <origin rpy="0 0 0" xyz="0.075 0 -0.05"/>
      <geometry>
        <sphere radius="0.005"/>
      </geometry>
    </visual>
    <collision>
      <origin rpy="0 0 0" xyz="0.075 0 -0.05"/>
      <geometry>
        <sphere radius="0.0"/>
      </geometry>
    </collision>
    <visual>
      <origin rpy="0 0 0" xyz="-0.075 0 -0.05"/>
      <geometry>
        <sphere radius="0.005"/>
      </geometry>
    </visual>
    <collision>
      <origin rpy="0 0 0" xyz="-0.075 0 -0.05"/>
      <geometry>
        <sphere radius="0.0"/>
      </geometry>
    </collision>
  </link>
  <joint name="l_ankle"
    type="revolute">
    <origin
      xyz="0 -0.0239 -0.26"
      rpy="0 0 0" />
    <parent
      link="l_lleg" />
    <child
      link="l_foot" />
    <axis
      xyz="0 1 0" />
    <limit
      lower="-1.39"
      upper="0.78"
      effort="48"
      velocity="25" />
  </joint>
  <transmission type="SimpleTransmission">
    <joint name="l_ankle"/>
    <actuator name="l_ankle_motor">
      <drake:gear_ratio value="9.0" />
      <drake:rotor_inertia value="0.0001002" />
    </actuator>
  </transmission>
  <link name="l_foot_x">
    <inertial>
      <origin
        xyz="0 0 -0.05"
        rpy="0 0 0" />
      <mass
        value="0.1" />
      <inertia
        ixx="1e-5"
        ixy="0"
        ixz="0"
        iyy="1e-5"
        iyz="0"
        izz="1e-5" />
    </inertial>
    <visual>
      <origin xyz="0.05 0 0" rpy="0 0 0" />
      <geometry>
        <box size="0.1 0.001 0.001" />
      </geometry>
      <material>
        <color rgba="1 0 0 1"/>
      </material>
    </visual>
    <visual>
      <origin xyz="0 0.05 0" rpy="0 0 0" />
      <geometry>
        <box size="0.001 0.1 0.001" />
      </geometry>
      <material>
        <color rgba="0 1 0 1"/>
      </material>
    </visual>
    <visual>
      <origin xyz="0 0 0.05" rpy="0 0 0" />
      <geometry>
        <box size="0.001 0.001 0.1" />
      </geometry>
      <material>
        <color rgba="0 0 1 1"/>
      </material>
    </visual>
  </link>
  <frame link="l_foot_x" name="l_foot_sole" xyz="0 0 0"/>
  <frame link="l_foot_x" name="l_foot_toe" xyz="0.075 0 0"/>
  <frame link="l_foot_x" name="l_foot_heel" xyz="-0.075 0 0"/>
  <joint name="l_ankle_x"
    type="fixed">
    <origin
      xyz="0 0 -0.05"
      rpy="0 0 0" />
    <parent
      link="l_foot" />
    <child
      link="l_foot_x" />
    <axis
      xyz="1 0 0" />
    <!-- <limit
      lower="-1.57"
      upper="1.57"
      effort="48"
      velocity="25" /> -->
  </joint>
  <!-- <transmission type="SimpleTransmission">
    <joint name="l_ankle_x"/>
    <actuator name="l_ankle_x_motor"/>
  </transmission> -->
  <link name="r_uleg_z">
    <inertial>
      <origin
        xyz="-0.086894 1.1718E-10 -0.019971"
        rpy="0 0 0" />
      <mass
        value="0.23915" />
      <inertia
        ixx="0.00019621"
        ixy="2.8207E-08"
        ixz="-0.00020599"
        iyy="0.000693"
        iyz="2.8208E-08"
        izz="0.00052444" />
    </inertial>
    <visual>
      <origin
        xyz="0 0 0"
        rpy="0 0 0" />
      <geometry>
        <mesh
          filename="../meshes/r_uleg_z.obj" />
      </geometry>
      <material
        name="">
        <color
          rgba="0.86667 0.86667 0.8902 1" />
      </material>
    </visual>
  </link>
  <joint name="r_hip_z"
    type="revolute">
    <origin
      xyz="0 -0.11 -0.0965"
      rpy="0 0 0" />
    <parent
      link="torso" />
    <child
      link="r_uleg_z" />
    <axis
      xyz="0 0 1" />
    <limit
      lower="-1.57"
      upper="1.57"
      effort="48"
      velocity="25" />
  </joint>
  <transmission type="SimpleTransmission">
    <joint name="r_hip_z"/>
    <actuator name="r_hip_z_motor">
      <drake:gear_ratio value="9.0" />
      <drake:rotor_inertia value="0.0001002" />
    </actuator>
  </transmission>
  <link name="r_uleg_x">
    <inertial>
      <origin
        xyz="0.091614 0.033814 -6.3136E-05"
        rpy="0 0 0" />
      <mass
        value="2.4984" />
      <inertia
        ixx="0.0028694"
        ixy="-0.00028224"
        ixz="-2.7675E-06"
        iyy="0.0035087"
        iyz="6.8462E-07"
        izz="0.0028259" />
    </inertial>
    <visual>
      <origin
        xyz="0 0 0"
        rpy="0 0 0" />
      <geometry>
        <mesh
          filename="../meshes/r_uleg_x.obj" />
      </geometry>
      <material
        name="">
        <color
          rgba="0.75294 0.75294 0.75294 1" />
      </material>
    </visual>
  </link>
  <joint name="r_hip_x"
    type="revolute">
    <origin
      xyz="-0.1335 0 -0.08"
      rpy="0 0 0" />
    <parent
      link="r_uleg_z" />
    <child
      link="r_uleg_x" />
    <axis
      xyz="1 0 0" />
    <limit
      lower="-1.57"
      upper="0.78"
      effort="48"
      velocity="25" />
  </joint>
  <transmission type="SimpleTransmission">
    <joint name="r_hip_x"/>
    <actuator name="r_hip_x_motor">
      <drake:gear_ratio value="9.0" />
      <drake:rotor_inertia value="0.0001002" />
    </actuator>
  </transmission>
  <link name="r_uleg">
    <inertial>
      <origin
        xyz="0.00097425 -0.021838 -0.021516"
        rpy="0 0 0" />
      <mass
        value="2.2508" />
      <inertia
        ixx="0.0073847"
        ixy="3.0173E-05"
        ixz="0.0003777"
        iyy="0.0095158"
        iyz="-0.00052695"
        izz="0.0025913" />
    </inertial>
    <visual>
      <origin
        xyz="0 0 0"
        rpy="0 0 0" />
      <geometry>
        <mesh
          filename="../meshes/r_uleg.obj" />
      </geometry>
      <material
        name="">
        <color
          rgba="0.75294 0.75294 0.75294 1" />
      </material>
    </visual>
  </link>
  <joint name="r_hip_y"
    type="revolute">
    <origin
      xyz="0.1355 0.00 0"
      rpy="0 0 0" />
    <parent
      link="r_uleg_x" />
    <child
      link="r_uleg" />
    <axis
      xyz="0 1 0" />
    <limit
      lower="-2.35"
      upper="0.78"
      effort="74"
      velocity="47" />
  </joint>
  <transmission type="SimpleTransmission">
    <joint name="r_hip_y"/>
    <actuator name="r_hip_y_motor">
      <drake:gear_ratio value="9.0" />
      <drake:rotor_inertia value="0.0001002" />
    </actuator>
  </transmission>
  <link name="r_knee_dummy">
    <inertial>
      <origin xyz="0 0 0" rpy="0 0 0"/>
      <mass value="0.1"/>
      <inertia ixx="1e-4" iyy="1e-4" izz="1e-4"/>
    </inertial>
  </link>
  <joint name="r_knee_dummy" type="revolute">
    <origin xyz="0 -0.03365 -0.23" rpy="0 0 0"/>
    <parent link="r_uleg"/>
    <child link="r_knee_dummy"/>
    <axis xyz="0 1 0"/>
    <limit upper="3.14" lower="-3.14"/>
    <dynamics damping="0"/>
  </joint>
  <drake:linear_bushing_rpy>
    <drake:bushing_frameA name="r_uleg"/>
    <drake:bushing_frameC name="r_knee_dummy"/>
    <drake:bushing_force_damping value="0 0 0"/>
    <drake:bushing_force_stiffness value="0 0 0"/>
    <drake:bushing_torque_damping value="0 10 0"/>
    <drake:bushing_torque_stiffness value="0 3000 0"/>
  </drake:linear_bushing_rpy>
  <link name="r_lleg">
    <inertial>
      <origin
        xyz="1.503E-05 0.03165 -0.018335"
        rpy="0 0 0" />
      <mass
        value="1.3508" />
      <inertia
        ixx="0.0040863"
        ixy="-5.3705E-08"
        ixz="-6.3356E-07"
        iyy="0.0046773"
        iyz="5.8528E-05"
        izz="0.0011018" />
    </inertial>
    <visual>
      <origin
        xyz="0 0 0"
        rpy="0 0 0" />
      <geometry>
        <mesh
          filename="../meshes/r_lleg.obj" />
      </geometry>
      <material
        name="">
        <color
          rgba="0.75294 0.75294 0.75294 1" />
      </material>
    </visual>
  </link>
  <joint name="r_knee"
    type="revolute">
    <origin
      xyz="0 0 0"
      rpy="0 0 0" />
    <parent
      link="r_knee_dummy" />
    <child
      link="r_lleg" />
    <axis
      xyz="0 1 0" />
    <limit
      lower="-0.174"
      upper="2.61"
      effort="74"
      velocity="47" />
  </joint>
  <transmission type="SimpleTransmission">
    <joint name="r_knee"/>
    <actuator name="r_knee_motor">
      <drake:gear_ratio value="9.0" />
      <drake:rotor_inertia value="0.0001002" />
    </actuator>
  </transmission>
  <link name="r_foot">
    <inertial>
      <origin
        xyz="-0.0017117 0.0012414 -0.028758"
        rpy="0 0 0" />
      <mass
        value="0.19291" />
      <inertia
        ixx="6.7548E-05"
        ixy="5.0585E-06"
        ixz="1.3775E-05"
        iyy="0.00030983"
        iyz="-9.9127E-06"
        izz="0.00027205" />
    </inertial>
    <visual>
      <origin
        xyz="0 0 0"
        rpy="0 0 0" />
      <geometry>
        <mesh
          filename="../meshes/r_foot.obj" />
      </geometry>
      <material
        name="">
        <color
          rgba="0.75294 0.75294 0.75294 1" />
      </material>
    </visual>
    <visual>
      <origin rpy="0 0 0" xyz="0.075 0 -0.05"/>
      <geometry>
        <sphere radius="0.005"/>
      </geometry>
    </visual>
    <collision>
      <origin rpy="0 0 0" xyz="0.075 0 -0.05"/>
      <geometry>
        <sphere radius="0.0"/>
      </geometry>
    </collision>
    <visual>
      <origin rpy="0 0 0" xyz="-0.075 0 -0.05"/>
      <geometry>
        <sphere radius="0.005"/>
      </geometry>
    </visual>
    <collision>
      <origin rpy="0 0 0" xyz="-0.075 0 -0.05"/>
      <geometry>
        <sphere radius="0.0"/>
      </geometry>
    </collision>
  </link>
  <joint name="r_ankle"
    type="revolute">
    <origin
      xyz="0 0.0239 -0.26"
      rpy="0 0 0" />
    <parent
      link="r_lleg" />
    <child
      link="r_foot" />
    <axis
      xyz="0 1 0" />
    <limit
      lower="-1.39"
      upper="0.78"
      effort="48"
      velocity="25" />
  </joint>
  <transmission type="SimpleTransmission">
    <joint name="r_ankle"/>
    <actuator name="r_ankle_motor">
      <drake:gear_ratio value="9.0" />
      <drake:rotor_inertia value="0.0001002" />
    </actuator>
  </transmission>
  <link name="r_foot_x">
    <inertial>
      <origin
        xyz="0 0 -0.05"
        rpy="0 0 0" />
      <mass
        value="0.1" />
      <inertia
        ixx="1e-5"
        ixy="0"
        ixz="0"
        iyy="1e-5"
        iyz="0"
        izz="1e-5" />
    </inertial>
    <visual>
      <origin
        xyz="0 0 0"
        rpy="0 0 0" />
      <geometry>
        <box size="0.01 0.001 0.001"/>
      </geometry>
    </visual>
    <visual>
      <origin xyz="0.05 0 0" rpy="0 0 0" />
      <geometry>
        <box size="0.1 0.001 0.001" />
      </geometry>
      <material>
        <color rgba="1 0 0 1"/>
      </material>
    </visual>
    <visual>
      <origin xyz="0 0.05 0" rpy="0 0 0" />
      <geometry>
        <box size="0.001 0.1 0.001" />
      </geometry>
      <material>
        <color rgba="0 1 0 1"/>
      </material>
    </visual>
    <visual>
      <origin xyz="0 0 0.05" rpy="0 0 0" />
      <geometry>
        <box size="0.001 0.001 0.1" />
      </geometry>
      <material>
        <color rgba="0 0 1 1"/>
      </material>
    </visual>
  </link>
  <frame link="r_foot_x" name="r_foot_sole" xyz="0 0 0"/>
  <frame link="r_foot_x" name="r_foot_toe" xyz="0.075 0 0"/>
  <frame link="r_foot_x" name="r_foot_heel" xyz="-0.075 0 0"/>
  <joint name="r_ankle_x"
    type="fixed">
    <origin
      xyz="0 0 -0.05"
      rpy="0 0 0" />
    <parent
      link="r_foot" />
    <child
      link="r_foot_x" />
    <axis
      xyz="1 0 0" />
    <!-- <limit
      lower="-1.57"
      upper="1.57"
      effort="48"
      velocity="25" /> -->
  </joint>
  <!-- <transmission type="SimpleTransmission">
    <joint name="r_ankle_x"/>
    <actuator name="r_ankle_x_motor"/>
  </transmission> -->
</robot>